[2025-09-18T06:50:49.765+0000] {taskinstance.py:1956} INFO - Dependencies all met for dep_context=non-requeueable deps ti=<TaskInstance: full_pipeline_test_dag.equities_eod_writer_task manual__2025-09-18T06:39:09.668392+00:00 [queued]>
[2025-09-18T06:50:49.784+0000] {taskinstance.py:1956} INFO - Dependencies all met for dep_context=requeueable deps ti=<TaskInstance: full_pipeline_test_dag.equities_eod_writer_task manual__2025-09-18T06:39:09.668392+00:00 [queued]>
[2025-09-18T06:50:49.787+0000] {taskinstance.py:2170} INFO - Starting attempt 1 of 1
[2025-09-18T06:50:49.841+0000] {taskinstance.py:2191} INFO - Executing <Task(PythonOperator): equities_eod_writer_task> on 2025-09-18 06:39:09.668392+00:00
[2025-09-18T06:50:49.867+0000] {standard_task_runner.py:60} INFO - Started process 1315 to run task
[2025-09-18T06:50:49.874+0000] {standard_task_runner.py:87} INFO - Running: ['***', 'tasks', 'run', 'full_pipeline_test_dag', 'equities_eod_writer_task', 'manual__2025-09-18T06:39:09.668392+00:00', '--job-id', '22', '--raw', '--subdir', 'DAGS_FOLDER/full_pipeline_test_dag.py', '--cfg-path', '/tmp/tmpczkaz_6x']
[2025-09-18T06:50:49.882+0000] {standard_task_runner.py:88} INFO - Job 22: Subtask equities_eod_writer_task
[2025-09-18T06:50:50.044+0000] {task_command.py:423} INFO - Running <TaskInstance: full_pipeline_test_dag.equities_eod_writer_task manual__2025-09-18T06:39:09.668392+00:00 [running]> on host 0bf5d1194250
[2025-09-18T06:50:50.252+0000] {taskinstance.py:2480} INFO - Exporting env vars: AIRFLOW_CTX_DAG_OWNER='ho' AIRFLOW_CTX_DAG_ID='full_pipeline_test_dag' AIRFLOW_CTX_TASK_ID='equities_eod_writer_task' AIRFLOW_CTX_EXECUTION_DATE='2025-09-18T06:39:09.668392+00:00' AIRFLOW_CTX_TRY_NUMBER='1' AIRFLOW_CTX_DAG_RUN_ID='manual__2025-09-18T06:39:09.668392+00:00'
[2025-09-18T06:50:51.103+0000] {taskinstance.py:2698} ERROR - Task failed with exception
Traceback (most recent call last):
  File "/home/airflow/.local/lib/python3.10/site-packages/airflow/models/taskinstance.py", line 433, in _execute_task
    result = execute_callable(context=context, **execute_callable_kwargs)
  File "/home/airflow/.local/lib/python3.10/site-packages/airflow/operators/python.py", line 199, in execute
    return_value = self.execute_callable()
  File "/home/airflow/.local/lib/python3.10/site-packages/airflow/operators/python.py", line 216, in execute_callable
    return self.python_callable(*self.op_args, **self.op_kwargs)
  File "/opt/airflow/scripts/equities_eod_writer.py", line 41, in run_equities_eod_writer
    client.fput_object(BUCKET, s3_path, file_name)
  File "/home/airflow/.local/lib/python3.10/site-packages/minio/api.py", line 1053, in fput_object
    return self.put_object(
  File "/home/airflow/.local/lib/python3.10/site-packages/minio/api.py", line 2008, in put_object
    raise exc
  File "/home/airflow/.local/lib/python3.10/site-packages/minio/api.py", line 1954, in put_object
    return self._put_object(
  File "/home/airflow/.local/lib/python3.10/site-packages/minio/api.py", line 1783, in _put_object
    response = self._execute(
  File "/home/airflow/.local/lib/python3.10/site-packages/minio/api.py", line 440, in _execute
    region = self._get_region(bucket_name)
  File "/home/airflow/.local/lib/python3.10/site-packages/minio/api.py", line 497, in _get_region
    response = self._url_open(
  File "/home/airflow/.local/lib/python3.10/site-packages/minio/api.py", line 426, in _url_open
    raise response_error
minio.error.S3Error: S3 operation failed; code: NoSuchBucket, message: The specified bucket does not exist, resource: /quant, request_id: 18664DCDDB38C7E2, host_id: dd9025bab4ad464b049177c95eb6ebf374d3b3fd1af9251148b658df7ac2e3e8, bucket_name: quant
[2025-09-18T06:50:51.153+0000] {taskinstance.py:1138} INFO - Marking task as FAILED. dag_id=full_pipeline_test_dag, task_id=equities_eod_writer_task, execution_date=20250918T063909, start_date=20250918T065049, end_date=20250918T065051
[2025-09-18T06:50:51.181+0000] {standard_task_runner.py:107} ERROR - Failed to execute job 22 for task equities_eod_writer_task (S3 operation failed; code: NoSuchBucket, message: The specified bucket does not exist, resource: /quant, request_id: 18664DCDDB38C7E2, host_id: dd9025bab4ad464b049177c95eb6ebf374d3b3fd1af9251148b658df7ac2e3e8, bucket_name: quant; 1315)
[2025-09-18T06:50:51.224+0000] {local_task_job_runner.py:234} INFO - Task exited with return code 1
[2025-09-18T06:50:51.310+0000] {taskinstance.py:3280} INFO - 0 downstream tasks scheduled from follow-on schedule check
