[2025-09-18T06:42:31.163+0000] {taskinstance.py:1956} INFO - Dependencies all met for dep_context=non-requeueable deps ti=<TaskInstance: equities_eod_batch_dag.batch_equities_eod manual__2025-09-18T06:42:06.032355+00:00 [queued]>
[2025-09-18T06:42:31.186+0000] {taskinstance.py:1956} INFO - Dependencies all met for dep_context=requeueable deps ti=<TaskInstance: equities_eod_batch_dag.batch_equities_eod manual__2025-09-18T06:42:06.032355+00:00 [queued]>
[2025-09-18T06:42:31.187+0000] {taskinstance.py:2170} INFO - Starting attempt 1 of 1
[2025-09-18T06:42:31.218+0000] {taskinstance.py:2191} INFO - Executing <Task(PythonOperator): batch_equities_eod> on 2025-09-18 06:42:06.032355+00:00
[2025-09-18T06:42:31.262+0000] {standard_task_runner.py:60} INFO - Started process 830 to run task
[2025-09-18T06:42:31.277+0000] {standard_task_runner.py:87} INFO - Running: ['***', 'tasks', 'run', 'equities_eod_batch_dag', 'batch_equities_eod', 'manual__2025-09-18T06:42:06.032355+00:00', '--job-id', '19', '--raw', '--subdir', 'DAGS_FOLDER/equities_eod_batch_dag.py', '--cfg-path', '/tmp/tmpe6y4z_vv']
[2025-09-18T06:42:31.287+0000] {standard_task_runner.py:88} INFO - Job 19: Subtask batch_equities_eod
[2025-09-18T06:42:31.559+0000] {task_command.py:423} INFO - Running <TaskInstance: equities_eod_batch_dag.batch_equities_eod manual__2025-09-18T06:42:06.032355+00:00 [running]> on host 0bf5d1194250
[2025-09-18T06:42:33.357+0000] {taskinstance.py:2480} INFO - Exporting env vars: AIRFLOW_CTX_DAG_OWNER='ho' AIRFLOW_CTX_DAG_ID='equities_eod_batch_dag' AIRFLOW_CTX_TASK_ID='batch_equities_eod' AIRFLOW_CTX_EXECUTION_DATE='2025-09-18T06:42:06.032355+00:00' AIRFLOW_CTX_TRY_NUMBER='1' AIRFLOW_CTX_DAG_RUN_ID='manual__2025-09-18T06:42:06.032355+00:00'
[2025-09-18T06:43:09.142+0000] {taskinstance.py:2698} ERROR - Task failed with exception
Traceback (most recent call last):
  File "/home/airflow/.local/lib/python3.10/site-packages/airflow/models/taskinstance.py", line 433, in _execute_task
    result = execute_callable(context=context, **execute_callable_kwargs)
  File "/home/airflow/.local/lib/python3.10/site-packages/airflow/operators/python.py", line 199, in execute
    return_value = self.execute_callable()
  File "/home/airflow/.local/lib/python3.10/site-packages/airflow/operators/python.py", line 216, in execute_callable
    return self.python_callable(*self.op_args, **self.op_kwargs)
  File "/opt/airflow/scripts/equities_eod_writer.py", line 41, in run_equities_eod_writer
    client.fput_object(BUCKET, s3_path, file_name)
  File "/home/airflow/.local/lib/python3.10/site-packages/minio/api.py", line 1053, in fput_object
    return self.put_object(
  File "/home/airflow/.local/lib/python3.10/site-packages/minio/api.py", line 2008, in put_object
    raise exc
  File "/home/airflow/.local/lib/python3.10/site-packages/minio/api.py", line 1954, in put_object
    return self._put_object(
  File "/home/airflow/.local/lib/python3.10/site-packages/minio/api.py", line 1783, in _put_object
    response = self._execute(
  File "/home/airflow/.local/lib/python3.10/site-packages/minio/api.py", line 440, in _execute
    region = self._get_region(bucket_name)
  File "/home/airflow/.local/lib/python3.10/site-packages/minio/api.py", line 497, in _get_region
    response = self._url_open(
  File "/home/airflow/.local/lib/python3.10/site-packages/minio/api.py", line 426, in _url_open
    raise response_error
minio.error.S3Error: S3 operation failed; code: NoSuchBucket, message: The specified bucket does not exist, resource: /quant, request_id: 18664D6248374D79, host_id: dd9025bab4ad464b049177c95eb6ebf374d3b3fd1af9251148b658df7ac2e3e8, bucket_name: quant
[2025-09-18T06:43:09.368+0000] {taskinstance.py:1138} INFO - Marking task as FAILED. dag_id=equities_eod_batch_dag, task_id=batch_equities_eod, execution_date=20250918T064206, start_date=20250918T064231, end_date=20250918T064309
[2025-09-18T06:43:09.499+0000] {standard_task_runner.py:107} ERROR - Failed to execute job 19 for task batch_equities_eod (S3 operation failed; code: NoSuchBucket, message: The specified bucket does not exist, resource: /quant, request_id: 18664D6248374D79, host_id: dd9025bab4ad464b049177c95eb6ebf374d3b3fd1af9251148b658df7ac2e3e8, bucket_name: quant; 830)
[2025-09-18T06:43:09.585+0000] {local_task_job_runner.py:234} INFO - Task exited with return code 1
[2025-09-18T06:43:09.794+0000] {taskinstance.py:3280} INFO - 0 downstream tasks scheduled from follow-on schedule check
